Workbook
Name Segment_Nom_commune: #N/A
Name Segment_Type_chantier: #N/A

Sheet BDD_SUIVI_CHANTIERS
A1: code_insee | B1: commune | C1: type | D1: latitude | E1: longitude | F1: a_faire | G1: EXISTANT / A CRÉER
A2: 14009 | B2: Amfreville | C2: Dalle cabane à cartons | D2: 49.25562438639887 | E2: -0.22937048501071255 | F2: DALLE A FAIRE
A3: 14070 | B3: Beuvron-en-Auge | C3: Dalle cabane à cartons | D3: 49.18846261113245 | E3: -0.04899986696358147 | F3: DALLE A FAIRE
A4: 14070 | B4: Beuvron-en-Auge | C4: Dalle cabane à cartons | D4: 49.18842466474889 | E4: -0.04898877950306013 | F4: DALLE A FAIRE
A5: 14117 | B5: Cabourg | C5: Dalle cabane à cartons | D5: 49.28669799293465 | E5: -0.1120432138904809 | F5: DALLE A FAIRE
A6: 14117 | B6: Cabourg | C6: Dalle cabane à cartons | D6: 49.282596795045436 | E6: -0.11971317218487827 | F6: DALLE A FAIRE
A7: 14203 | B7: Cricqueville-en-Auge | C7: Dalle cabane à cartons | D7: 49.25049652130896 | E7: -0.06291898739405613 | F7: DALLE A FAIRE
A8: 14229 | B8: Dozulé | C8: Dalle cabane à cartons | D8: 49.22709487115593 | E8: -0.04823379090339059 | F8: DALLE A FAIRE
A9: 14229 | B9: Dozulé | C9: Dalle cabane à cartons | D9: 49.233704768397914 | E9: -0.0500232074070623 | F9: DALLE A FAIRE
A10: 14229 | B10: Dozulé | C10: Dalle cabane à cartons | D10: 49.23177507654163 | E10: -0.04427842285725417 | F10: DALLE A FAIRE
A11: 14231 | B11: Beaufour-Druval | C11: Dalle cabane à cartons | D11: 49.21497388373563 | E11: 0.021471329987151584 | F11: DALLE A FAIRE
A12: 14246 | B12: Escoville | C12: Dalle cabane à cartons | D12: 49.210131672560685 | E12: -0.23835679485422115 | F12: DALLE A FAIRE
A13: 14306 | B13: Gonneville-en-Auge | C13: Dalle cabane à cartons | D13: 49.26070201771357 | E13: -0.19127903845914065 | F13: DALLE A FAIRE
... A50: 14743 | B50: Victot-Pontfol | C50: Dalle borne à verre | D50: 49.1729147854973 | E50: -0.018277632373220002 | F50: DALLE A FAIRE
A51: 14009 | B51: Amfreville | C51: Dalle PDR | D51: 49.249052346825934 | E51: -0.23480492949435036 | F51: DALLE A FAIRE | G51: A AMÉNAGER
A52: 14009 | B52: Amfreville | C52: Dalle PDR | D52: 49.249052346825934 | E52: -0.23480492949435036 | F52: DALLE A FAIRE | G52: A AMÉNAGER
A53: 14012 | B53: Angerville | C53: Dalle PDR | D53: 49.2472318 | E53: -0.0129685 | F53: DALLE A FAIRE | G53: A AGRANDIR
A54: 14012 | B54: Angerville | C54: Dalle PDR | D54: 49.2400787 | E54: -0.0191979 | F54: DALLE A FAIRE | G54: A AMÉNAGER
A55: 14012 | B55: Angerville | C55: Dalle PDR | D55: 49.244207 | E55: -0.0395653 | F55: DALLE A FAIRE | G55: A CRÉER
A56: 14012 | B56: Angerville | C56: Dalle PDR | D56: 49.2481283 | E56: -0.0366497 | F56: DALLE A FAIRE | G56: A CRÉER
A57: 14024 | B57: Auberville | C57: Dalle PDR | D57: 49.3065861 | E57: -0.0288498 | F57: DALLE A FAIRE | G57: A AMÉNAGER
A58: 14024 | B58: Auberville | C58: Dalle PDR | D58: 49.31762117435177 | E58: -0.015299902973347072 | F58: DALLE A FAIRE | G58: A AMÉNAGER
A59: 14045 | B59: Basseneville | C59: Dalle PDR | D59: 49.2076913 | E59: -0.1189426 | F59: DALLE A FAIRE | G59: A AGRANDIR
A60: 14045 | B60: Basseneville | C60: Dalle PDR | D60: 49.21135 | E60: -0.1158996 | F60: DALLE A FAIRE | G60: A AGRANDIR
A61: 14045 | B61: Basseneville | C61: Dalle PDR | D61: 49.199983 | E61: -0.1501742 | F61: DALLE A FAIRE | G61: A AGRANDIR
A62: 14045 | B62: Basseneville | C62: Dalle PDR | D62: 49.20935103640219 | E62: -0.15287255054911186 | F62: DALLE A FAIRE | G62: A AGRANDIR
... A137: 14724 | B137: Varaville | C137: Dalle PDR | D137: 49.2833384235042 | E137: -0.1689880342290415 | F137: DALLE A FAIRE | G137: A CRÉER
A138: 14743 | B138: Victot-en-Auge | C138: Dalle PDR | F138: DALLE A FAIRE | G138: A AMÉNAGER
A139: 14743 | B139: Victot-en-Auge | C139: Dalle PDR | D139: 49.1928515263001 | E139: -0.0050519618974088016 | F139: DALLE A FAIRE | G139: A AMÉNAGER
A140: 14743 | B140: Victot-en-Auge | C140: Dalle PDR | D140: 49.162830781875286 | E140: -0.016482885130563795 | F140: DALLE A FAIRE | G140: A AMÉNAGER
A141: 14743 | B141: Victot-en-Auge | C141: Dalle PDR | D141: 49.16015134123915 | E141: -0.012098838971738815 | F141: DALLE A FAIRE | G141: A AMÉNAGER
A142: 14743 | B142: Victot-en-Auge | C142: Dalle PDR | D142: 49.15227122363916 | E142: -0.006458452353706777 | F142: DALLE A FAIRE | G142: A AMÉNAGER
A143: 14743 | B143: Victot-en-Auge | C143: Dalle PDR | D143: 49.171809356230234 | E143: 0.007687174804642114 | F143: DALLE A FAIRE | G143: A ÉTUDIER

Sheet PRIORISATION-1
D22: Nombre de chantiers à réaliser par nature | G22: Détermination de la priorité
A23: Code INSEE | B23: Nom commune | C23: Priorité (1=urgente à 3) | D23: Cabanes à cartons | E23: PDR | F23: Dalles borne à verre | G23: Priorité globale | H23: Score pondéré | I23: ORDRE | L23: Pondérations (modifiables)
A24: 14012 | B24: Angerville | C24: 1 | D24: =+COUNTIFS(BDD_SUIVI_CHANTIERS[code_insee],'PRIORISATION-1'!A24,BDD_SUIVI_CHANTIERS[type],"Dalle cabane à cartons") -> 0 | E24: =+COUNTIFS(BDD_SUIVI_CHANTIERS[code_insee],'PRIORISATION-1'!A24,BDD_SUIVI_CHANTIERS[type],"DALLE PDR") -> 4 | F24: =+COUNTIFS(BDD_SUIVI_CHANTIERS[code_insee],'PRIORISATION-1'!A24,BDD_SUIVI_CHANTIERS[type],"Dalle borne à verre") -> 0 | G24: =IF($H24>=$M$33,"P1 - Critique",IF($H24>=$M$34,"P2 - Haute",IF($H24>=$M$35,"P3 - Moyenne","P4 - Basse"))) -> P2 - Haute | H24: {=INDEX($M$24:$M$27,$C24)+IFERROR(VLOOKUP(N($D24),$L$54:$M$57,2,TRUE),0)+IFERROR(VLOOKUP(N($E24),$L$39:$M$43,2,TRUE),0)+IFERROR(VLOOKUP(N($F24),$L$47:$M$50,2,TRUE),0)} -> 45 | I24: =+RANK(H24,$H$24:$H$61,0) -> 12 | L24: Base - priorité historique 1 | M24: 30
A25: 14229 | B25: Dozulé | C25: 3 | D25: =+COUNTIFS(BDD_SUIVI_CHANTIERS[code_insee],'PRIORISATION-1'!A25,BDD_SUIVI_CHANTIERS[type],"Dalle cabane à cartons") -> 3 | E25: =+COUNTIFS(BDD_SUIVI_CHANTIERS[code_insee],'PRIORISATION-1'!A25,BDD_SUIVI_CHANTIERS[type],"DALLE PDR") -> 9 | F25: =+COUNTIFS(BDD_SUIVI_CHANTIERS[code_insee],'PRIORISATION-1'!A25,BDD_SUIVI_CHANTIERS[type],"Dalle borne à verre") -> 1 | G25: =IF($H25>=$M$33,"P1 - Critique",IF($H25>=$M$34,"P2 - Haute",IF($H25>=$M$35,"P3 - Moyenne","P4 - Basse"))) -> P1 - Critique | H25: {=INDEX($M$24:$M$27,$C25)+IFERROR(VLOOKUP(N($D25),$L$54:$M$57,2,TRUE),0)+IFERROR(VLOOKUP(N($E25),$L$39:$M$43,2,TRUE),0)+IFERROR(VLOOKUP(N($F25),$L$47:$M$50,2,TRUE),0)} -> 59 | I25: =+RANK(H25,$H$24:$H$61,0) -> 6 | L25: Base - priorité historique 2 | M25: 20
A26: 14305 | B26: Gonneville-sur-Mer | C26: 1 | D26: =+COUNTIFS(BDD_SUIVI_CHANTIERS[code_insee],'PRIORISATION-1'!A26,BDD_SUIVI_CHANTIERS[type],"Dalle cabane à cartons") -> 0 | E26: =+COUNTIFS(BDD_SUIVI_CHANTIERS[code_insee],'PRIORISATION-1'!A26,BDD_SUIVI_CHANTIERS[type],"DALLE PDR") -> 10 | F26: =+COUNTIFS(BDD_SUIVI_CHANTIERS[code_insee],'PRIORISATION-1'!A26,BDD_SUIVI_CHANTIERS[type],"Dalle borne à verre") -> 2 | G26: =IF($H26>=$M$33,"P1 - Critique",IF($H26>=$M$34,"P2 - Haute",IF($H26>=$M$35,"P3 - Moyenne","P4 - Basse"))) -> P1 - Critique | H26: {=INDEX($M$24:$M$27,$C26)+IFERROR(VLOOKUP(N($D26),$L$54:$M$57,2,TRUE),0)+IFERROR(VLOOKUP(N($E26),$L$39:$M$43,2,TRUE),0)+IFERROR(VLOOKUP(N($F26),$L$47:$M$50,2,TRUE),0)} -> 63 | I26: =+RANK(H26,$H$24:$H$61,0) -> 5 | L26: Base - priorité historique 3 | M26: 10
A27: 14335 | B27: Hotot-en-Auge | C27: 1 | D27: =+COUNTIFS(BDD_SUIVI_CHANTIERS[code_insee],'PRIORISATION-1'!A27,BDD_SUIVI_CHANTIERS[type],"Dalle cabane à cartons") -> 0 | E27: =+COUNTIFS(BDD_SUIVI_CHANTIERS[code_insee],'PRIORISATION-1'!A27,BDD_SUIVI_CHANTIERS[type],"DALLE PDR") -> 0 | F27: =+COUNTIFS(BDD_SUIVI_CHANTIERS[code_insee],'PRIORISATION-1'!A27,BDD_SUIVI_CHANTIERS[type],"Dalle borne à verre") -> 0 | G27: =IF($H27>=$M$33,"P1 - Critique",IF($H27>=$M$34,"P2 - Haute",IF($H27>=$M$35,"P3 - Moyenne","P4 - Basse"))) -> P3 - Moyenne | H27: {=INDEX($M$24:$M$27,$C27)+IFERROR(VLOOKUP(N($D27),$L$54:$M$57,2,TRUE),0)+IFERROR(VLOOKUP(N($E27),$L$39:$M$43,2,TRUE),0)+IFERROR(VLOOKUP(N($F27),$L$47:$M$50,2,TRUE),0)} -> 30 | I27: =+RANK(H27,$H$24:$H$61,0) -> 21 | L27: Base - priorité historique 4 | M27: 0
A28: 14550 | B28: Rumesnil | C28: 1 | D28: =+COUNTIFS(BDD_SUIVI_CHANTIERS[code_insee],'PRIORISATION-1'!A28,BDD_SUIVI_CHANTIERS[type],"Dalle cabane à cartons") -> 0 | E28: =+COUNTIFS(BDD_SUIVI_CHANTIERS[code_insee],'PRIORISATION-1'!A28,BDD_SUIVI_CHANTIERS[type],"DALLE PDR") -> 2 | F28: =+COUNTIFS(BDD_SUIVI_CHANTIERS[code_insee],'PRIORISATION-1'!A28,BDD_SUIVI_CHANTIERS[type],"Dalle borne à verre") -> 1 | G28: =IF($H28>=$M$33,"P1 - Critique",IF($H28>=$M$34,"P2 - Haute",IF($H28>=$M$35,"P3 - Moyenne","P4 - Basse"))) -> P2 - Haute | H28: {=INDEX($M$24:$M$27,$C28)+IFERROR(VLOOKUP(N($D28),$L$54:$M$57,2,TRUE),0)+IFERROR(VLOOKUP(N($E28),$L$39:$M$43,2,TRUE),0)+IFERROR(VLOOKUP(N($F28),$L$47:$M$50,2,TRUE),0)} -> 44 | I28: =+RANK(H28,$H$24:$H$61,0) -> 14 | L28: Bonus cabanes à cartons : voir barème ci-dessous
A29: 14665 | B29: Sallenelles | C29: 2 | D29: =+COUNTIFS(BDD_SUIVI_CHANTIERS[code_insee],'PRIORISATION-1'!A29,BDD_SUIVI_CHANTIERS[type],"Dalle cabane à cartons") -> 1 | E29: =+COUNTIFS(BDD_SUIVI_CHANTIERS[code_insee],'PRIORISATION-1'!A29,BDD_SUIVI_CHANTIERS[type],"DALLE PDR") -> 2 | F29: =+COUNTIFS(BDD_SUIVI_CHANTIERS[code_insee],'PRIORISATION-1'!A29,BDD_SUIVI_CHANTIERS[type],"Dalle borne à verre") -> 1 | G29: =IF($H29>=$M$33,"P1 - Critique",IF($H29>=$M$34,"P2 - Haute",IF($H29>=$M$35,"P3 - Moyenne","P4 - Basse"))) -> P2 - Haute | H29: {=INDEX($M$24:$M$27,$C29)+IFERROR(VLOOKUP(N($D29),$L$54:$M$57,2,TRUE),0)+IFERROR(VLOOKUP(N($E29),$L$39:$M$43,2,TRUE),0)+IFERROR(VLOOKUP(N($F29),$L$47:$M$50,2,TRUE),0)} -> 49 | I29: =+RANK(H29,$H$24:$H$61,0) -> 9 | L29: Bonus PDR : voir barème ci-dessous
A30: 14743 | B30: Victot-en-Auge | C30: 2 | D30: =+COUNTIFS(BDD_SUIVI_CHANTIERS[code_insee],'PRIORISATION-1'!A30,BDD_SUIVI_CHANTIERS[type],"Dalle cabane à cartons") -> 2 | E30: =+COUNTIFS(BDD_SUIVI_CHANTIERS[code_insee],'PRIORISATION-1'!A30,BDD_SUIVI_CHANTIERS[type],"DALLE PDR") -> 6 | F30: =+COUNTIFS(BDD_SUIVI_CHANTIERS[code_insee],'PRIORISATION-1'!A30,BDD_SUIVI_CHANTIERS[type],"Dalle borne à verre") -> 1 | G30: =IF($H30>=$M$33,"P1 - Critique",IF($H30>=$M$34,"P2 - Haute",IF($H30>=$M$35,"P3 - Moyenne","P4 - Basse"))) -> P1 - Critique | H30: {=INDEX($M$24:$M$27,$C30)+IFERROR(VLOOKUP(N($D30),$L$54:$M$57,2,TRUE),0)+IFERROR(VLOOKUP(N($E30),$L$39:$M$43,2,TRUE),0)+IFERROR(VLOOKUP(N($F30),$L$47:$M$50,2,TRUE),0)} -> 64 | I30: =+RANK(H30,$H$24:$H$61,0) -> 4
A31: 14198 | B31: Cresseveuille | C31: 2 | D31: =+COUNTIFS(BDD_SUIVI_CHANTIERS[code_insee],'PRIORISATION-1'!A31,BDD_SUIVI_CHANTIERS[type],"Dalle cabane à cartons") -> 0 | E31: =+COUNTIFS(BDD_SUIVI_CHANTIERS[code_insee],'PRIORISATION-1'!A31,BDD_SUIVI_CHANTIERS[type],"DALLE PDR") -> 1 | F31: =+COUNTIFS(BDD_SUIVI_CHANTIERS[code_insee],'PRIORISATION-1'!A31,BDD_SUIVI_CHANTIERS[type],"Dalle borne à verre") -> 1 | G31: =IF($H31>=$M$33,"P1 - Critique",IF($H31>=$M$34,"P2 - Haute",IF($H31>=$M$35,"P3 - Moyenne","P4 - Basse"))) -> P3 - Moyenne | H31: {=INDEX($M$24:$M$27,$C31)+IFERROR(VLOOKUP(N($D31),$L$54:$M$57,2,TRUE),0)+IFERROR(VLOOKUP(N($E31),$L$39:$M$43,2,TRUE),0)+IFERROR(VLOOKUP(N($F31),$L$47:$M$50,2,TRUE),0)} -> 34 | I31: =+RANK(H31,$H$24:$H$61,0) -> 19 | L31: Bonus bornes à verre : voir barème ci-dessous
A32: 14203 | B32: Cricqueville-en-Auge | C32: 2 | D32: =+COUNTIFS(BDD_SUIVI_CHANTIERS[code_insee],'PRIORISATION-1'!A32,BDD_SUIVI_CHANTIERS[type],"Dalle cabane à cartons") -> 1 | E32: =+COUNTIFS(BDD_SUIVI_CHANTIERS[code_insee],'PRIORISATION-1'!A32,BDD_SUIVI_CHANTIERS[type],"DALLE PDR") -> 1 | F32: =+COUNTIFS(BDD_SUIVI_CHANTIERS[code_insee],'PRIORISATION-1'!A32,BDD_SUIVI_CHANTIERS[type],"Dalle borne à verre") -> 0 | G32: =IF($H32>=$M$33,"P1 - Critique",IF($H32>=$M$34,"P2 - Haute",IF($H32>=$M$35,"P3 - Moyenne","P4 - Basse"))) -> P2 - Haute | H32: {=INDEX($M$24:$M$27,$C32)+IFERROR(VLOOKUP(N($D32),$L$54:$M$57,2,TRUE),0)+IFERROR(VLOOKUP(N($E32),$L$39:$M$43,2,TRUE),0)+IFERROR(VLOOKUP(N($F32),$L$47:$M$50,2,TRUE),0)} -> 45 | I32: =+RANK(H32,$H$24:$H$61,0) -> 12
A33: 14227 | B33: Douville-en-Auge | C33: 2 | D33: =+COUNTIFS(BDD_SUIVI_CHANTIERS[code_insee],'PRIORISATION-1'!A33,BDD_SUIVI_CHANTIERS[type],"Dalle cabane à cartons") -> 0 | E33: =+COUNTIFS(BDD_SUIVI_CHANTIERS[code_insee],'PRIORISATION-1'!A33,BDD_SUIVI_CHANTIERS[type],"DALLE PDR") -> 3 | F33: =+COUNTIFS(BDD_SUIVI_CHANTIERS[code_insee],'PRIORISATION-1'!A33,BDD_SUIVI_CHANTIERS[type],"Dalle borne à verre") -> 1 | G33: =IF($H33>=$M$33,"P1 - Critique",IF($H33>=$M$34,"P2 - Haute",IF($H33>=$M$35,"P3 - Moyenne","P4 - Basse"))) -> P3 - Moyenne | H33: {=INDEX($M$24:$M$27,$C33)+IFERROR(VLOOKUP(N($D33),$L$54:$M$57,2,TRUE),0)+IFERROR(VLOOKUP(N($E33),$L$39:$M$43,2,TRUE),0)+IFERROR(VLOOKUP(N($F33),$L$47:$M$50,2,TRUE),0)} -> 39 | I33: =+RANK(H33,$H$24:$H$61,0) -> 17 | L33: Seuil classe P1 - Critique | M33: 55
A34: 14306 | B34: Gonneville-en-Auge | C34: 2 | D34: =+COUNTIFS(BDD_SUIVI_CHANTIERS[code_insee],'PRIORISATION-1'!A34,BDD_SUIVI_CHANTIERS[type],"Dalle cabane à cartons") -> 1 | E34: =+COUNTIFS(BDD_SUIVI_CHANTIERS[code_insee],'PRIORISATION-1'!A34,BDD_SUIVI_CHANTIERS[type],"DALLE PDR") -> 3 | F34: =+COUNTIFS(BDD_SUIVI_CHANTIERS[code_insee],'PRIORISATION-1'!A34,BDD_SUIVI_CHANTIERS[type],"Dalle borne à verre") -> 1 | G34: =IF($H34>=$M$33,"P1 - Critique",IF($H34>=$M$34,"P2 - Haute",IF($H34>=$M$35,"P3 - Moyenne","P4 - Basse"))) -> P2 - Haute | H34: {=INDEX($M$24:$M$27,$C34)+IFERROR(VLOOKUP(N($D34),$L$54:$M$57,2,TRUE),0)+IFERROR(VLOOKUP(N($E34),$L$39:$M$43,2,TRUE),0)+IFERROR(VLOOKUP(N($F34),$L$47:$M$50,2,TRUE),0)} -> 54 | I34: =+RANK(H34,$H$24:$H$61,0) -> 8 | L34: Seuil classe P2 - Haute | M34: 40
A35: 14308 | B35: Goustranville | C35: 2 | D35: =+COUNTIFS(BDD_SUIVI_CHANTIERS[code_insee],'PRIORISATION-1'!A35,BDD_SUIVI_CHANTIERS[type],"Dalle cabane à cartons") -> 0 | E35: =+COUNTIFS(BDD_SUIVI_CHANTIERS[code_insee],'PRIORISATION-1'!A35,BDD_SUIVI_CHANTIERS[type],"DALLE PDR") -> 1 | F35: =+COUNTIFS(BDD_SUIVI_CHANTIERS[code_insee],'PRIORISATION-1'!A35,BDD_SUIVI_CHANTIERS[type],"Dalle borne à verre") -> 0 | G35: =IF($H35>=$M$33,"P1 - Critique",IF($H35>=$M$34,"P2 - Haute",IF($H35>=$M$35,"P3 - Moyenne","P4 - Basse"))) -> P3 - Moyenne | H35: {=INDEX($M$24:$M$27,$C35)+IFERROR(VLOOKUP(N($D35),$L$54:$M$57,2,TRUE),0)+IFERROR(VLOOKUP(N($E35),$L$39:$M$43,2,TRUE),0)+IFERROR(VLOOKUP(N($F35),$L$47:$M$50,2,TRUE),0)} -> 30 | I35: =+RANK(H35,$H$24:$H$61,0) -> 21 | L35: Seuil classe P3 - Moyenne | M35: 30
A36: 14316 | B36: Grangues | C36: 1 | D36: =+COUNTIFS(BDD_SUIVI_CHANTIERS[code_insee],'PRIORISATION-1'!A36,BDD_SUIVI_CHANTIERS[type],"Dalle cabane à cartons") -> 1 | E36: =+COUNTIFS(BDD_SUIVI_CHANTIERS[code_insee],'PRIORISATION-1'!A36,BDD_SUIVI_CHANTIERS[type],"DALLE PDR") -> 8 | F36: =+COUNTIFS(BDD_SUIVI_CHANTIERS[code_insee],'PRIORISATION-1'!A36,BDD_SUIVI_CHANTIERS[type],"Dalle borne à verre") -> 0 | G36: =IF($H36>=$M$33,"P1 - Critique",IF($H36>=$M$34,"P2 - Haute",IF($H36>=$M$35,"P3 - Moyenne","P4 - Basse"))) -> P1 - Critique | H36: {=INDEX($M$24:$M$27,$C36)+IFERROR(VLOOKUP(N($D36),$L$54:$M$57,2,TRUE),0)+IFERROR(VLOOKUP(N($E36),$L$39:$M$43,2,TRUE),0)+IFERROR(VLOOKUP(N($F36),$L$47:$M$50,2,TRUE),0)} -> 65 | I36: =+RANK(H36,$H$24:$H$61,0) -> 3
A37: 14045 | B37: Basseneville | C37: 3 | D37: =+COUNTIFS(BDD_SUIVI_CHANTIERS[code_insee],'PRIORISATION-1'!A37,BDD_SUIVI_CHANTIERS[type],"Dalle cabane à cartons") -> 0 | E37: =+COUNTIFS(BDD_SUIVI_CHANTIERS[code_insee],'PRIORISATION-1'!A37,BDD_SUIVI_CHANTIERS[type],"DALLE PDR") -> 4 | F37: =+COUNTIFS(BDD_SUIVI_CHANTIERS[code_insee],'PRIORISATION-1'!A37,BDD_SUIVI_CHANTIERS[type],"Dalle borne à verre") -> 0 | G37: =IF($H37>=$M$33,"P1 - Critique",IF($H37>=$M$34,"P2 - Haute",IF($H37>=$M$35,"P3 - Moyenne","P4 - Basse"))) -> P4 - Basse | H37: {=INDEX($M$24:$M$27,$C37)+IFERROR(VLOOKUP(N($D37),$L$54:$M$57,2,TRUE),0)+IFERROR(VLOOKUP(N($E37),$L$39:$M$43,2,TRUE),0)+IFERROR(VLOOKUP(N($F37),$L$47:$M$50,2,TRUE),0)} -> 25 | I37: =+RANK(H37,$H$24:$H$61,0) -> 25 | L37: Barème PDR (nb de dalles PDR à créer)
A38: 14231 | B38: Beaufour-Druval | C38: 3 | D38: =+COUNTIFS(BDD_SUIVI_CHANTIERS[code_insee],'PRIORISATION-1'!A38,BDD_SUIVI_CHANTIERS[type],"Dalle cabane à cartons") -> 1 | E38: =+COUNTIFS(BDD_SUIVI_CHANTIERS[code_insee],'PRIORISATION-1'!A38,BDD_SUIVI_CHANTIERS[type],"DALLE PDR") -> 1 | F38: =+COUNTIFS(BDD_SUIVI_CHANTIERS[code_insee],'PRIORISATION-1'!A38,BDD_SUIVI_CHANTIERS[type],"Dalle borne à verre") -> 0 | G38: =IF($H38>=$M$33,"P1 - Critique",IF($H38>=$M$34,"P2 - Haute",IF($H38>=$M$35,"P3 - Moyenne","P4 - Basse"))) -> P3 - Moyenne | H38: {=INDEX($M$24:$M$27,$C38)+IFERROR(VLOOKUP(N($D38),$L$54:$M$57,2,TRUE),0)+IFERROR(VLOOKUP(N($E38),$L$39:$M$43,2,TRUE),0)+IFERROR(VLOOKUP(N($F38),$L$47:$M$50,2,TRUE),0)} -> 35 | I38: =+RANK(H38,$H$24:$H$61,0) -> 18 | L38: Nb de PDR ≥ | M38: Bonus
A39: 14070 | B39: Beuvron-en-Auge | C39: 3 | D39: =+COUNTIFS(BDD_SUIVI_CHANTIERS[code_insee],'PRIORISATION-1'!A39,BDD_SUIVI_CHANTIERS[type],"Dalle cabane à cartons") -> 2 | E39: =+COUNTIFS(BDD_SUIVI_CHANTIERS[code_insee],'PRIORISATION-1'!A39,BDD_SUIVI_CHANTIERS[type],"DALLE PDR") -> 2 | F39: =+COUNTIFS(BDD_SUIVI_CHANTIERS[code_insee],'PRIORISATION-1'!A39,BDD_SUIVI_CHANTIERS[type],"Dalle borne à verre") -> 0 | G39: =IF($H39>=$M$33,"P1 - Critique",IF($H39>=$M$34,"P2 - Haute",IF($H39>=$M$35,"P3 - Moyenne","P4 - Basse"))) -> P2 - Haute | H39: {=INDEX($M$24:$M$27,$C39)+IFERROR(VLOOKUP(N($D39),$L$54:$M$57,2,TRUE),0)+IFERROR(VLOOKUP(N($E39),$L$39:$M$43,2,TRUE),0)+IFERROR(VLOOKUP(N($F39),$L$47:$M$50,2,TRUE),0)} -> 40 | I39: =+RANK(H39,$H$24:$H$61,0) -> 15 | L39: 0 | M39: 0
A40: 14110 | B40: Brucourt | C40: 3 | D40: =+COUNTIFS(BDD_SUIVI_CHANTIERS[code_insee],'PRIORISATION-1'!A40,BDD_SUIVI_CHANTIERS[type],"Dalle cabane à cartons") -> 0 | E40: =+COUNTIFS(BDD_SUIVI_CHANTIERS[code_insee],'PRIORISATION-1'!A40,BDD_SUIVI_CHANTIERS[type],"DALLE PDR") -> 3 | F40: =+COUNTIFS(BDD_SUIVI_CHANTIERS[code_insee],'PRIORISATION-1'!A40,BDD_SUIVI_CHANTIERS[type],"Dalle borne à verre") -> 1 | G40: =IF($H40>=$M$33,"P1 - Critique",IF($H40>=$M$34,"P2 - Haute",IF($H40>=$M$35,"P3 - Moyenne","P4 - Basse"))) -> P4 - Basse | H40: {=INDEX($M$24:$M$27,$C40)+IFERROR(VLOOKUP(N($D40),$L$54:$M$57,2,TRUE),0)+IFERROR(VLOOKUP(N($E40),$L$39:$M$43,2,TRUE),0)+IFERROR(VLOOKUP(N($F40),$L$47:$M$50,2,TRUE),0)} -> 29 | I40: =+RANK(H40,$H$24:$H$61,0) -> 23 | L40: 1 | M40: 10
A41: 14524 | B41: Putot-en-Auge | C41: 3 | D41: =+COUNTIFS(BDD_SUIVI_CHANTIERS[code_insee],'PRIORISATION-1'!A41,BDD_SUIVI_CHANTIERS[type],"Dalle cabane à cartons") -> 1 | E41: =+COUNTIFS(BDD_SUIVI_CHANTIERS[code_insee],'PRIORISATION-1'!A41,BDD_SUIVI_CHANTIERS[type],"DALLE PDR") -> 0 | F41: =+COUNTIFS(BDD_SUIVI_CHANTIERS[code_insee],'PRIORISATION-1'!A41,BDD_SUIVI_CHANTIERS[type],"Dalle borne à verre") -> 0 | G41: =IF($H41>=$M$33,"P1 - Critique",IF($H41>=$M$34,"P2 - Haute",IF($H41>=$M$35,"P3 - Moyenne","P4 - Basse"))) -> P4 - Basse | H41: {=INDEX($M$24:$M$27,$C41)+IFERROR(VLOOKUP(N($D41),$L$54:$M$57,2,TRUE),0)+IFERROR(VLOOKUP(N($E41),$L$39:$M$43,2,TRUE),0)+IFERROR(VLOOKUP(N($F41),$L$47:$M$50,2,TRUE),0)} -> 25 | I41: =+RANK(H41,$H$24:$H$61,0) -> 25 | L41: 3 | M41: 15
A42: 14598 | B42: Saint-Jouin | C42: 3 | D42: =+COUNTIFS(BDD_SUIVI_CHANTIERS[code_insee],'PRIORISATION-1'!A42,BDD_SUIVI_CHANTIERS[type],"Dalle cabane à cartons") -> 1 | E42: =+COUNTIFS(BDD_SUIVI_CHANTIERS[code_insee],'PRIORISATION-1'!A42,BDD_SUIVI_CHANTIERS[type],"DALLE PDR") -> 3 | F42: =+COUNTIFS(BDD_SUIVI_CHANTIERS[code_insee],'PRIORISATION-1'!A42,BDD_SUIVI_CHANTIERS[type],"Dalle borne à verre") -> 0 | G42: =IF($H42>=$M$33,"P1 - Critique",IF($H42>=$M$34,"P2 - Haute",IF($H42>=$M$35,"P3 - Moyenne","P4 - Basse"))) -> P2 - Haute | H42: {=INDEX($M$24:$M$27,$C42)+IFERROR(VLOOKUP(N($D42),$L$54:$M$57,2,TRUE),0)+IFERROR(VLOOKUP(N($E42),$L$39:$M$43,2,TRUE),0)+IFERROR(VLOOKUP(N($F42),$L$47:$M$50,2,TRUE),0)} -> 40 | I42: =+RANK(H42,$H$24:$H$61,0) -> 15 | L42: 6 | M42: 20
A43: 14009 | B43: Amfreville | C43: 4 | D43: =+COUNTIFS(BDD_SUIVI_CHANTIERS[code_insee],'PRIORISATION-1'!A43,BDD_SUIVI_CHANTIERS[type],"Dalle cabane à cartons") -> 1 | E43: =+COUNTIFS(BDD_SUIVI_CHANTIERS[code_insee],'PRIORISATION-1'!A43,BDD_SUIVI_CHANTIERS[type],"DALLE PDR") -> 2 | F43: =+COUNTIFS(BDD_SUIVI_CHANTIERS[code_insee],'PRIORISATION-1'!A43,BDD_SUIVI_CHANTIERS[type],"Dalle borne à verre") -> 2 | G43: =IF($H43>=$M$33,"P1 - Critique",IF($H43>=$M$34,"P2 - Haute",IF($H43>=$M$35,"P3 - Moyenne","P4 - Basse"))) -> P3 - Moyenne | H43: {=INDEX($M$24:$M$27,$C43)+IFERROR(VLOOKUP(N($D43),$L$54:$M$57,2,TRUE),0)+IFERROR(VLOOKUP(N($E43),$L$39:$M$43,2,TRUE),0)+IFERROR(VLOOKUP(N($F43),$L$47:$M$50,2,TRUE),0)} -> 33 | I43: =+RANK(H43,$H$24:$H$61,0) -> 20 | L43: 10 | M43: 25
A44: 14024 | B44: Auberville | C44: 4 | D44: =+COUNTIFS(BDD_SUIVI_CHANTIERS[code_insee],'PRIORISATION-1'!A44,BDD_SUIVI_CHANTIERS[type],"Dalle cabane à cartons") -> 0 | E44: =+COUNTIFS(BDD_SUIVI_CHANTIERS[code_insee],'PRIORISATION-1'!A44,BDD_SUIVI_CHANTIERS[type],"DALLE PDR") -> 2 | F44: =+COUNTIFS(BDD_SUIVI_CHANTIERS[code_insee],'PRIORISATION-1'!A44,BDD_SUIVI_CHANTIERS[type],"Dalle borne à verre") -> 1 | G44: =IF($H44>=$M$33,"P1 - Critique",IF($H44>=$M$34,"P2 - Haute",IF($H44>=$M$35,"P3 - Moyenne","P4 - Basse"))) -> P4 - Basse | H44: {=INDEX($M$24:$M$27,$C44)+IFERROR(VLOOKUP(N($D44),$L$54:$M$57,2,TRUE),0)+IFERROR(VLOOKUP(N($E44),$L$39:$M$43,2,TRUE),0)+IFERROR(VLOOKUP(N($F44),$L$47:$M$50,2,TRUE),0)} -> 14 | I44: =+RANK(H44,$H$24:$H$61,0) -> 29
A45: 14046 | B45: Bavent | C45: 4 | D45: =+COUNTIFS(BDD_SUIVI_CHANTIERS[code_insee],'PRIORISATION-1'!A45,BDD_SUIVI_CHANTIERS[type],"Dalle cabane à cartons") -> 0 | E45: =+COUNTIFS(BDD_SUIVI_CHANTIERS[code_insee],'PRIORISATION-1'!A45,BDD_SUIVI_CHANTIERS[type],"DALLE PDR") -> 6 | F45: =+COUNTIFS(BDD_SUIVI_CHANTIERS[code_insee],'PRIORISATION-1'!A45,BDD_SUIVI_CHANTIERS[type],"Dalle borne à verre") -> 2 | G45: =IF($H45>=$M$33,"P1 - Critique",IF($H45>=$M$34,"P2 - Haute",IF($H45>=$M$35,"P3 - Moyenne","P4 - Basse"))) -> P4 - Basse | H45: {=INDEX($M$24:$M$27,$C45)+IFERROR(VLOOKUP(N($D45),$L$54:$M$57,2,TRUE),0)+IFERROR(VLOOKUP(N($E45),$L$39:$M$43,2,TRUE),0)+IFERROR(VLOOKUP(N($F45),$L$47:$M$50,2,TRUE),0)} -> 28 | I45: =+RANK(H45,$H$24:$H$61,0) -> 24 | L45: Barème bornes à verre (nb de dalles à créer)
A46: 14106 | B46: Bréville-les-Monts | C46: 4 | D46: =+COUNTIFS(BDD_SUIVI_CHANTIERS[code_insee],'PRIORISATION-1'!A46,BDD_SUIVI_CHANTIERS[type],"Dalle cabane à cartons") -> 0 | E46: =+COUNTIFS(BDD_SUIVI_CHANTIERS[code_insee],'PRIORISATION-1'!A46,BDD_SUIVI_CHANTIERS[type],"DALLE PDR") -> 1 | F46: =+COUNTIFS(BDD_SUIVI_CHANTIERS[code_insee],'PRIORISATION-1'!A46,BDD_SUIVI_CHANTIERS[type],"Dalle borne à verre") -> 1 | G46: =IF($H46>=$M$33,"P1 - Critique",IF($H46>=$M$34,"P2 - Haute",IF($H46>=$M$35,"P3 - Moyenne","P4 - Basse"))) -> P4 - Basse | H46: {=INDEX($M$24:$M$27,$C46)+IFERROR(VLOOKUP(N($D46),$L$54:$M$57,2,TRUE),0)+IFERROR(VLOOKUP(N($E46),$L$39:$M$43,2,TRUE),0)+IFERROR(VLOOKUP(N($F46),$L$47:$M$50,2,TRUE),0)} -> 14 | I46: =+RANK(H46,$H$24:$H$61,0) -> 29 | L46: Nb de bornes ≥ | M46: Bonus
A47: 14117 | B47: Cabourg | C47: 1 | D47: =+COUNTIFS(BDD_SUIVI_CHANTIERS[code_insee],'PRIORISATION-1'!A47,BDD_SUIVI_CHANTIERS[type],"Dalle cabane à cartons") -> 2 | E47: =+COUNTIFS(BDD_SUIVI_CHANTIERS[code_insee],'PRIORISATION-1'!A47,BDD_SUIVI_CHANTIERS[type],"DALLE PDR") -> 2 | F47: =+COUNTIFS(BDD_SUIVI_CHANTIERS[code_insee],'PRIORISATION-1'!A47,BDD_SUIVI_CHANTIERS[type],"Dalle borne à verre") -> 3 | G47: =IF($H47>=$M$33,"P1 - Critique",IF($H47>=$M$34,"P2 - Haute",IF($H47>=$M$35,"P3 - Moyenne","P4 - Basse"))) -> P1 - Critique | H47: {=INDEX($M$24:$M$27,$C47)+IFERROR(VLOOKUP(N($D47),$L$54:$M$57,2,TRUE),0)+IFERROR(VLOOKUP(N($E47),$L$39:$M$43,2,TRUE),0)+IFERROR(VLOOKUP(N($F47),$L$47:$M$50,2,TRUE),0)} -> 72 | I47: =+RANK(H47,$H$24:$H$61,0) -> 1 | L47: 0 | M47: 0
A48: 14225 | B48: Dives-sur-Mer | C48: 1 | D48: =+COUNTIFS(BDD_SUIVI_CHANTIERS[code_insee],'PRIORISATION-1'!A48,BDD_SUIVI_CHANTIERS[type],"Dalle cabane à cartons") -> 0 | E48: =+COUNTIFS(BDD_SUIVI_CHANTIERS[code_insee],'PRIORISATION-1'!A48,BDD_SUIVI_CHANTIERS[type],"DALLE PDR") -> 3 | F48: =+COUNTIFS(BDD_SUIVI_CHANTIERS[code_insee],'PRIORISATION-1'!A48,BDD_SUIVI_CHANTIERS[type],"Dalle borne à verre") -> 4 | G48: =IF($H48>=$M$33,"P1 - Critique",IF($H48>=$M$34,"P2 - Haute",IF($H48>=$M$35,"P3 - Moyenne","P4 - Basse"))) -> P1 - Critique | H48: {=INDEX($M$24:$M$27,$C48)+IFERROR(VLOOKUP(N($D48),$L$54:$M$57,2,TRUE),0)+IFERROR(VLOOKUP(N($E48),$L$39:$M$43,2,TRUE),0)+IFERROR(VLOOKUP(N($F48),$L$47:$M$50,2,TRUE),0)} -> 57 | I48: =+RANK(H48,$H$24:$H$61,0) -> 7 | L48: 1 | M48: 4
A49: 14246 | B49: Escoville | C49: 4 | D49: =+COUNTIFS(BDD_SUIVI_CHANTIERS[code_insee],'PRIORISATION-1'!A49,BDD_SUIVI_CHANTIERS[type],"Dalle cabane à cartons") -> 1 | E49: =+COUNTIFS(BDD_SUIVI_CHANTIERS[code_insee],'PRIORISATION-1'!A49,BDD_SUIVI_CHANTIERS[type],"DALLE PDR") -> 0 | F49: =+COUNTIFS(BDD_SUIVI_CHANTIERS[code_insee],'PRIORISATION-1'!A49,BDD_SUIVI_CHANTIERS[type],"Dalle borne à verre") -> 0 | G49: =IF($H49>=$M$33,"P1 - Critique",IF($H49>=$M$34,"P2 - Haute",IF($H49>=$M$35,"P3 - Moyenne","P4 - Basse"))) -> P4 - Basse | H49: {=INDEX($M$24:$M$27,$C49)+IFERROR(VLOOKUP(N($D49),$L$54:$M$57,2,TRUE),0)+IFERROR(VLOOKUP(N($E49),$L$39:$M$43,2,TRUE),0)+IFERROR(VLOOKUP(N($F49),$L$47:$M$50,2,TRUE),0)} -> 15 | I49: =+RANK(H49,$H$24:$H$61,0) -> 28 | L49: 2 | M49: 8
A50: 14328 | B50: Hérouvillette | C50: 4 | D50: =+COUNTIFS(BDD_SUIVI_CHANTIERS[code_insee],'PRIORISATION-1'!A50,BDD_SUIVI_CHANTIERS[type],"Dalle cabane à cartons") -> 0 | E50: =+COUNTIFS(BDD_SUIVI_CHANTIERS[code_insee],'PRIORISATION-1'!A50,BDD_SUIVI_CHANTIERS[type],"DALLE PDR") -> 0 | F50: =+COUNTIFS(BDD_SUIVI_CHANTIERS[code_insee],'PRIORISATION-1'!A50,BDD_SUIVI_CHANTIERS[type],"Dalle borne à verre") -> 0 | G50: =IF($H50>=$M$33,"P1 - Critique",IF($H50>=$M$34,"P2 - Haute",IF($H50>=$M$35,"P3 - Moyenne","P4 - Basse"))) -> P4 - Basse | H50: {=INDEX($M$24:$M$27,$C50)+IFERROR(VLOOKUP(N($D50),$L$54:$M$57,2,TRUE),0)+IFERROR(VLOOKUP(N($E50),$L$39:$M$43,2,TRUE),0)+IFERROR(VLOOKUP(N($F50),$L$47:$M$50,2,TRUE),0)} -> 0 | I50: =+RANK(H50,$H$24:$H$61,0) -> 34 | L50: 3 | M50: 12
A51: 14329 | B51: Heuland | C51: 4 | D51: =+COUNTIFS(BDD_SUIVI_CHANTIERS[code_insee],'PRIORISATION-1'!A51,BDD_SUIVI_CHANTIERS[type],"Dalle cabane à cartons") -> 0 | E51: =+COUNTIFS(BDD_SUIVI_CHANTIERS[code_insee],'PRIORISATION-1'!A51,BDD_SUIVI_CHANTIERS[type],"DALLE PDR") -> 1 | F51: =+COUNTIFS(BDD_SUIVI_CHANTIERS[code_insee],'PRIORISATION-1'!A51,BDD_SUIVI_CHANTIERS[type],"Dalle borne à verre") -> 0 | G51: =IF($H51>=$M$33,"P1 - Critique",IF($H51>=$M$34,"P2 - Haute",IF($H51>=$M$35,"P3 - Moyenne","P4 - Basse"))) -> P4 - Basse | H51: {=INDEX($M$24:$M$27,$C51)+IFERROR(VLOOKUP(N($D51),$L$54:$M$57,2,TRUE),0)+IFERROR(VLOOKUP(N($E51),$L$39:$M$43,2,TRUE),0)+IFERROR(VLOOKUP(N($F51),$L$47:$M$50,2,TRUE),0)} -> 10 | I51: =+RANK(H51,$H$24:$H$61,0) -> 31
A52: 14338 | B52: Houlgate | C52: 1 | D52: =+COUNTIFS(BDD_SUIVI_CHANTIERS[code_insee],'PRIORISATION-1'!A52,BDD_SUIVI_CHANTIERS[type],"Dalle cabane à cartons") -> 1 | E52: =+COUNTIFS(BDD_SUIVI_CHANTIERS[code_insee],'PRIORISATION-1'!A52,BDD_SUIVI_CHANTIERS[type],"DALLE PDR") -> 6 | F52: =+COUNTIFS(BDD_SUIVI_CHANTIERS[code_insee],'PRIORISATION-1'!A52,BDD_SUIVI_CHANTIERS[type],"Dalle borne à verre") -> 1 | G52: =IF($H52>=$M$33,"P1 - Critique",IF($H52>=$M$34,"P2 - Haute",IF($H52>=$M$35,"P3 - Moyenne","P4 - Basse"))) -> P1 - Critique | H52: {=INDEX($M$24:$M$27,$C52)+IFERROR(VLOOKUP(N($D52),$L$54:$M$57,2,TRUE),0)+IFERROR(VLOOKUP(N($E52),$L$39:$M$43,2,TRUE),0)+IFERROR(VLOOKUP(N($F52),$L$47:$M$50,2,TRUE),0)} -> 69 | I52: =+RANK(H52,$H$24:$H$61,0) -> 2 | L52: Barème cabanes à cartons (nb de dalles à créer)
A53: 14409 | B53: Merville-Franceville-Plage | C53: 1 | D53: =+COUNTIFS(BDD_SUIVI_CHANTIERS[code_insee],'PRIORISATION-1'!A53,BDD_SUIVI_CHANTIERS[type],"Dalle cabane à cartons") -> 0 | E53: =+COUNTIFS(BDD_SUIVI_CHANTIERS[code_insee],'PRIORISATION-1'!A53,BDD_SUIVI_CHANTIERS[type],"DALLE PDR") -> 2 | F53: =+COUNTIFS(BDD_SUIVI_CHANTIERS[code_insee],'PRIORISATION-1'!A53,BDD_SUIVI_CHANTIERS[type],"Dalle borne à verre") -> 2 | G53: =IF($H53>=$M$33,"P1 - Critique",IF($H53>=$M$34,"P2 - Haute",IF($H53>=$M$35,"P3 - Moyenne","P4 - Basse"))) -> P2 - Haute | H53: {=INDEX($M$24:$M$27,$C53)+IFERROR(VLOOKUP(N($D53),$L$54:$M$57,2,TRUE),0)+IFERROR(VLOOKUP(N($E53),$L$39:$M$43,2,TRUE),0)+IFERROR(VLOOKUP(N($F53),$L$47:$M$50,2,TRUE),0)} -> 48 | I53: =+RANK(H53,$H$24:$H$61,0) -> 11 | L53: Nb de cabanes ≥ | M53: Bonus
A54: 14494 | B54: Périers-en-Auge | C54: 4 | D54: =+COUNTIFS(BDD_SUIVI_CHANTIERS[code_insee],'PRIORISATION-1'!A54,BDD_SUIVI_CHANTIERS[type],"Dalle cabane à cartons") -> 0 | E54: =+COUNTIFS(BDD_SUIVI_CHANTIERS[code_insee],'PRIORISATION-1'!A54,BDD_SUIVI_CHANTIERS[type],"DALLE PDR") -> 0 | F54: =+COUNTIFS(BDD_SUIVI_CHANTIERS[code_insee],'PRIORISATION-1'!A54,BDD_SUIVI_CHANTIERS[type],"Dalle borne à verre") -> 0 | G54: =IF($H54>=$M$33,"P1 - Critique",IF($H54>=$M$34,"P2 - Haute",IF($H54>=$M$35,"P3 - Moyenne","P4 - Basse"))) -> P4 - Basse | H54: {=INDEX($M$24:$M$27,$C54)+IFERROR(VLOOKUP(N($D54),$L$54:$M$57,2,TRUE),0)+IFERROR(VLOOKUP(N($E54),$L$39:$M$43,2,TRUE),0)+IFERROR(VLOOKUP(N($F54),$L$47:$M$50,2,TRUE),0)} -> 0 | I54: =+RANK(H54,$H$24:$H$61,0) -> 34 | L54: 0 | M54: 0
A55: 14499 | B55: Petiville | C55: 4 | D55: =+COUNTIFS(BDD_SUIVI_CHANTIERS[code_insee],'PRIORISATION-1'!A55,BDD_SUIVI_CHANTIERS[type],"Dalle cabane à cartons") -> 0 | E55: =+COUNTIFS(BDD_SUIVI_CHANTIERS[code_insee],'PRIORISATION-1'!A55,BDD_SUIVI_CHANTIERS[type],"DALLE PDR") -> 0 | F55: =+COUNTIFS(BDD_SUIVI_CHANTIERS[code_insee],'PRIORISATION-1'!A55,BDD_SUIVI_CHANTIERS[type],"Dalle borne à verre") -> 0 | G55: =IF($H55>=$M$33,"P1 - Critique",IF($H55>=$M$34,"P2 - Haute",IF($H55>=$M$35,"P3 - Moyenne","P4 - Basse"))) -> P4 - Basse | H55: {=INDEX($M$24:$M$27,$C55)+IFERROR(VLOOKUP(N($D55),$L$54:$M$57,2,TRUE),0)+IFERROR(VLOOKUP(N($E55),$L$39:$M$43,2,TRUE),0)+IFERROR(VLOOKUP(N($F55),$L$47:$M$50,2,TRUE),0)} -> 0 | I55: =+RANK(H55,$H$24:$H$61,0) -> 34 | L55: 1 | M55: 15
A56: 14530 | B56: Ranville | C56: 4 | D56: =+COUNTIFS(BDD_SUIVI_CHANTIERS[code_insee],'PRIORISATION-1'!A56,BDD_SUIVI_CHANTIERS[type],"Dalle cabane à cartons") -> 1 | E56: =+COUNTIFS(BDD_SUIVI_CHANTIERS[code_insee],'PRIORISATION-1'!A56,BDD_SUIVI_CHANTIERS[type],"DALLE PDR") -> 0 | F56: =+COUNTIFS(BDD_SUIVI_CHANTIERS[code_insee],'PRIORISATION-1'!A56,BDD_SUIVI_CHANTIERS[type],"Dalle borne à verre") -> 1 | G56: =IF($H56>=$M$33,"P1 - Critique",IF($H56>=$M$34,"P2 - Haute",IF($H56>=$M$35,"P3 - Moyenne","P4 - Basse"))) -> P4 - Basse | H56: {=INDEX($M$24:$M$27,$C56)+IFERROR(VLOOKUP(N($D56),$L$54:$M$57,2,TRUE),0)+IFERROR(VLOOKUP(N($E56),$L$39:$M$43,2,TRUE),0)+IFERROR(VLOOKUP(N($F56),$L$47:$M$50,2,TRUE),0)} -> 19 | I56: =+RANK(H56,$H$24:$H$61,0) -> 27 | L56: 2 | M56: 20
A57: 14606 | B57: Saint-Léger-Dubosq | C57: 4 | D57: =+COUNTIFS(BDD_SUIVI_CHANTIERS[code_insee],'PRIORISATION-1'!A57,BDD_SUIVI_CHANTIERS[type],"Dalle cabane à cartons") -> 0 | E57: =+COUNTIFS(BDD_SUIVI_CHANTIERS[code_insee],'PRIORISATION-1'!A57,BDD_SUIVI_CHANTIERS[type],"DALLE PDR") -> 1 | F57: =+COUNTIFS(BDD_SUIVI_CHANTIERS[code_insee],'PRIORISATION-1'!A57,BDD_SUIVI_CHANTIERS[type],"Dalle borne à verre") -> 0 | G57: =IF($H57>=$M$33,"P1 - Critique",IF($H57>=$M$34,"P2 - Haute",IF($H57>=$M$35,"P3 - Moyenne","P4 - Basse"))) -> P4 - Basse | H57: {=INDEX($M$24:$M$27,$C57)+IFERROR(VLOOKUP(N($D57),$L$54:$M$57,2,TRUE),0)+IFERROR(VLOOKUP(N($E57),$L$39:$M$43,2,TRUE),0)+IFERROR(VLOOKUP(N($F57),$L$47:$M$50,2,TRUE),0)} -> 10 | I57: =+RANK(H57,$H$24:$H$61,0) -> 31 | L57: 3 | M57: 25
A58: 14657 | B58: Saint-Samson | C58: 4 | D58: =+COUNTIFS(BDD_SUIVI_CHANTIERS[code_insee],'PRIORISATION-1'!A58,BDD_SUIVI_CHANTIERS[type],"Dalle cabane à cartons") -> 0 | E58: =+COUNTIFS(BDD_SUIVI_CHANTIERS[code_insee],'PRIORISATION-1'!A58,BDD_SUIVI_CHANTIERS[type],"DALLE PDR") -> 0 | F58: =+COUNTIFS(BDD_SUIVI_CHANTIERS[code_insee],'PRIORISATION-1'!A58,BDD_SUIVI_CHANTIERS[type],"Dalle borne à verre") -> 0 | G58: =IF($H58>=$M$33,"P1 - Critique",IF($H58>=$M$34,"P2 - Haute",IF($H58>=$M$35,"P3 - Moyenne","P4 - Basse"))) -> P4 - Basse | H58: {=INDEX($M$24:$M$27,$C58)+IFERROR(VLOOKUP(N($D58),$L$54:$M$57,2,TRUE),0)+IFERROR(VLOOKUP(N($E58),$L$39:$M$43,2,TRUE),0)+IFERROR(VLOOKUP(N($F58),$L$47:$M$50,2,TRUE),0)} -> 0 | I58: =+RANK(H58,$H$24:$H$61,0) -> 34
A59: 14660 | B59: Saint-Vaast-en-Auge | C59: 4 | D59: =+COUNTIFS(BDD_SUIVI_CHANTIERS[code_insee],'PRIORISATION-1'!A59,BDD_SUIVI_CHANTIERS[type],"Dalle cabane à cartons") -> 0 | E59: =+COUNTIFS(BDD_SUIVI_CHANTIERS[code_insee],'PRIORISATION-1'!A59,BDD_SUIVI_CHANTIERS[type],"DALLE PDR") -> 0 | F59: =+COUNTIFS(BDD_SUIVI_CHANTIERS[code_insee],'PRIORISATION-1'!A59,BDD_SUIVI_CHANTIERS[type],"Dalle borne à verre") -> 1 | G59: =IF($H59>=$M$33,"P1 - Critique",IF($H59>=$M$34,"P2 - Haute",IF($H59>=$M$35,"P3 - Moyenne","P4 - Basse"))) -> P4 - Basse | H59: {=INDEX($M$24:$M$27,$C59)+IFERROR(VLOOKUP(N($D59),$L$54:$M$57,2,TRUE),0)+IFERROR(VLOOKUP(N($E59),$L$39:$M$43,2,TRUE),0)+IFERROR(VLOOKUP(N($F59),$L$47:$M$50,2,TRUE),0)} -> 4 | I59: =+RANK(H59,$H$24:$H$61,0) -> 33
A60: 14698 | B60: Touffréville | C60: 4 | D60: =+COUNTIFS(BDD_SUIVI_CHANTIERS[code_insee],'PRIORISATION-1'!A60,BDD_SUIVI_CHANTIERS[type],"Dalle cabane à cartons") -> 0 | E60: =+COUNTIFS(BDD_SUIVI_CHANTIERS[code_insee],'PRIORISATION-1'!A60,BDD_SUIVI_CHANTIERS[type],"DALLE PDR") -> 0 | F60: =+COUNTIFS(BDD_SUIVI_CHANTIERS[code_insee],'PRIORISATION-1'!A60,BDD_SUIVI_CHANTIERS[type],"Dalle borne à verre") -> 0 | G60: =IF($H60>=$M$33,"P1 - Critique",IF($H60>=$M$34,"P2 - Haute",IF($H60>=$M$35,"P3 - Moyenne","P4 - Basse"))) -> P4 - Basse | H60: {=INDEX($M$24:$M$27,$C60)+IFERROR(VLOOKUP(N($D60),$L$54:$M$57,2,TRUE),0)+IFERROR(VLOOKUP(N($E60),$L$39:$M$43,2,TRUE),0)+IFERROR(VLOOKUP(N($F60),$L$47:$M$50,2,TRUE),0)} -> 0 | I60: =+RANK(H60,$H$24:$H$61,0) -> 34
A61: 14724 | B61: Varaville | C61: 1 | D61: =+COUNTIFS(BDD_SUIVI_CHANTIERS[code_insee],'PRIORISATION-1'!A61,BDD_SUIVI_CHANTIERS[type],"Dalle cabane à cartons") -> 0 | E61: =+COUNTIFS(BDD_SUIVI_CHANTIERS[code_insee],'PRIORISATION-1'!A61,BDD_SUIVI_CHANTIERS[type],"DALLE PDR") -> 4 | F61: =+COUNTIFS(BDD_SUIVI_CHANTIERS[code_insee],'PRIORISATION-1'!A61,BDD_SUIVI_CHANTIERS[type],"Dalle borne à verre") -> 1 | G61: =IF($H61>=$M$33,"P1 - Critique",IF($H61>=$M$34,"P2 - Haute",IF($H61>=$M$35,"P3 - Moyenne","P4 - Basse"))) -> P2 - Haute | H61: {=INDEX($M$24:$M$27,$C61)+IFERROR(VLOOKUP(N($D61),$L$54:$M$57,2,TRUE),0)+IFERROR(VLOOKUP(N($E61),$L$39:$M$43,2,TRUE),0)+IFERROR(VLOOKUP(N($F61),$L$47:$M$50,2,TRUE),0)} -> 49 | I61: =+RANK(H61,$H$24:$H$61,0) -> 9
...

Sheet PRIORISATION-ETAT
A1: {=_xlfn.HSTACK("Rang chantier","Ordre commune",BDD_SUIVI_CHANTIERS[#Headers])} -> Rang chantier | B1: Ordre commune | C1: code_insee | D1: commune | E1: type | F1: latitude | G1: longitude | H1: a_faire | I1: EXISTANT / A CRÉER | K1: Priorité type | L1: Rang
A2: {=_xlfn.LET(_xlpm.d,IF(BDD_SUIVI_CHANTIERS[]="","",BDD_SUIVI_CHANTIERS[]),_xlpm.o,_xlfn.XLOOKUP(BDD_SUIVI_CHANTIERS[code_insee],'PRIORISATION-1'!$A$24:$A$61,'PRIORISATION-1'!$I$24:$I$61,999),_xlpm.t,_xlfn.XLOOKUP(BDD_SUIVI_CHANTIERS[type],$K$2:$K$4,$L$2:$L$4,99),_xlpm.s,_xlfn.SORTBY(_xlfn.HSTACK(_xlpm.o,_xlpm.d),_xlpm.o,1,BDD_SUIVI_CHANTIERS[commune],1,_xlpm.t,1),_xlfn.HSTACK(_xlfn.SEQUENCE(ROWS(_xlpm.d)),_xlpm.s))} -> 1 | B2: 1 | C2: 14117 | D2: Cabourg | E2: Dalle cabane à cartons | F2: 49.28669799293465 | G2: -0.1120432138904809 | H2: DALLE A FAIRE | K2: Dalle cabane à cartons | L2: 1
A3: 2 | B3: 1 | C3: 14117 | D3: Cabourg | E3: Dalle cabane à cartons | F3: 49.282596795045436 | G3: -0.11971317218487827 | H3: DALLE A FAIRE | K3: Dalle PDR | L3: 2
A4: 3 | B4: 1 | C4: 14117 | D4: Cabourg | E4: Dalle PDR | F4: 49.2822898 | G4: -0.119475 | H4: DALLE A FAIRE | I4: A AMÉNAGER | K4: Dalle borne à verre | L4: 3
A5: 4 | B5: 1 | C5: 14117 | D5: Cabourg | E5: Dalle PDR | F5: 49.2905266 | G5: -0.1155201 | H5: DALLE A FAIRE | I5: A AMÉNAGER
A6: 5 | B6: 1 | C6: 14117 | D6: Cabourg | E6: Dalle borne à verre | F6: 49.28938402033412 | G6: -0.12674304087854937 | H6: DALLE A FAIRE
A7: 6 | B7: 1 | C7: 14117 | D7: Cabourg | E7: Dalle borne à verre | F7: 49.29424072245121 | G7: -0.10623969812685341 | H7: DALLE A FAIRE
A8: 7 | B8: 1 | C8: 14117 | D8: Cabourg | E8: Dalle borne à verre | F8: 49.27806 | G8: -0.13368 | H8: DALLE A FAIRE
A9: 8 | B9: 2 | C9: 14338 | D9: Houlgate | E9: Dalle cabane à cartons | F9: 49.292704990188746 | G9: -0.08016420280405341 | H9: DALLE A FAIRE
A10: 9 | B10: 2 | C10: 14338 | D10: Houlgate | E10: Dalle PDR | F10: 49.2876584 | G10: -0.0830063 | H10: DALLE A FAIRE | I10: A CRÉER
A11: 10 | B11: 2 | C11: 14338 | D11: Houlgate | E11: Dalle PDR | F11: 49.294539237574405 | G11: -0.07897841397117843 | H11: DALLE A FAIRE | I11: A AGRANDIR
A12: 11 | B12: 2 | C12: 14338 | D12: Houlgate | E12: Dalle PDR | F12: 49.2952025 | G12: -0.0566013 | H12: DALLE A FAIRE | I12: A AGRANDIR
A13: 12 | B13: 2 | C13: 14338 | D13: Houlgate | E13: Dalle PDR | F13: 49.29825875109513 | G13: -0.05468906257289417 | H13: DALLE A FAIRE | I13: A AGRANDIR
A14: 13 | B14: 2 | C14: 14338 | D14: Houlgate | E14: Dalle PDR | F14: 49.29988446178953 | G14: -0.05982123995887206 | H14: DALLE A FAIRE | I14: A AGRANDIR
A15: 14 | B15: 2 | C15: 14338 | D15: Houlgate | E15: Dalle PDR | F15: 49.302243628361495 | G15: -0.06986609035196993 | H15: DALLE A FAIRE | I15: A CRÉER
A16: 15 | B16: 2 | C16: 14338 | D16: Houlgate | E16: Dalle borne à verre | F16: 49.29294 | G16: -0.04829 | H16: DALLE A FAIRE
A17: 16 | B17: 3 | C17: 14316 | D17: Grangues | E17: Dalle cabane à cartons | F17: 49.265584155325584 | G17: -0.056620502222822604 | H17: DALLE A FAIRE
A18: 17 | B18: 3 | C18: 14316 | D18: Grangues | E18: Dalle PDR | F18: 49.26612615423531 | G18: -0.0823053498976165 | H18: DALLE A FAIRE | I18: A AGRANDIR
A19: 18 | B19: 3 | C19: 14316 | D19: Grangues | E19: Dalle PDR | F19: 49.2763151 | G19: -0.0654915 | H19: DALLE A FAIRE | I19: A CRÉER
A20: 19 | B20: 3 | C20: 14316 | D20: Grangues | E20: Dalle PDR | F20: 49.25905843312884 | G20: -0.05074849461745545 | H20: DALLE A FAIRE | I20: A CRÉER
A21: 20 | B21: 3 | C21: 14316 | D21: Grangues | E21: Dalle PDR | F21: 49.2592847 | G21: -0.0415662 | H21: DALLE A FAIRE | I21: A CRÉER
A22: 21 | B22: 3 | C22: 14316 | D22: Grangues | E22: Dalle PDR | F22: 49.2659712 | G22: -0.0646614 | H22: DALLE A FAIRE | I22: A CRÉER
A23: 22 | B23: 3 | C23: 14316 | D23: Grangues | E23: Dalle PDR | F23: 49.2724319 | G23: -0.0540277 | H23: DALLE A FAIRE | I23: A AGRANDIR
A24: 23 | B24: 3 | C24: 14316 | D24: Grangues | E24: Dalle PDR | F24: 49.26790536510873 | G24: -0.05590027026478743 | H24: DALLE A FAIRE | I24: A CRÉER
A25: 24 | B25: 3 | C25: 14316 | D25: Grangues | E25: Dalle PDR | F25: 49.262806168961625 | G25: -0.07378242105904796 | H25: DALLE A FAIRE | I25: A CRÉER
A26: 25 | B26: 4 | C26: 14743 | D26: Victot-en-Auge | E26: Dalle cabane à cartons | F26: 49.17289832707203 | G26: -0.018312847925501575 | H26: DALLE A FAIRE
A27: 26 | B27: 4 | C27: 14743 | D27: Victot-en-Auge | E27: Dalle cabane à cartons | F27: 49.16536420807095 | G27: 0.0031910194201919414 | H27: DALLE A FAIRE
A28: 27 | B28: 4 | C28: 14743 | D28: Victot-en-Auge | E28: Dalle PDR | H28: DALLE A FAIRE | I28: A AMÉNAGER
A29: 28 | B29: 4 | C29: 14743 | D29: Victot-en-Auge | E29: Dalle PDR | F29: 49.1928515263001 | G29: -0.0050519618974088016 | H29: DALLE A FAIRE | I29: A AMÉNAGER
A30: 29 | B30: 4 | C30: 14743 | D30: Victot-en-Auge | E30: Dalle PDR | F30: 49.162830781875286 | G30: -0.016482885130563795 | H30: DALLE A FAIRE | I30: A AMÉNAGER
A31: 30 | B31: 4 | C31: 14743 | D31: Victot-en-Auge | E31: Dalle PDR | F31: 49.16015134123915 | G31: -0.012098838971738815 | H31: DALLE A FAIRE | I31: A AMÉNAGER
A32: 31 | B32: 4 | C32: 14743 | D32: Victot-en-Auge | E32: Dalle PDR | F32: 49.15227122363916 | G32: -0.006458452353706777 | H32: DALLE A FAIRE | I32: A AMÉNAGER
A33: 32 | B33: 4 | C33: 14743 | D33: Victot-en-Auge | E33: Dalle PDR | F33: 49.171809356230234 | G33: 0.007687174804642114 | H33: DALLE A FAIRE | I33: A ÉTUDIER
A34: 33 | B34: 4 | C34: 14743 | D34: Victot-Pontfol | E34: Dalle borne à verre | F34: 49.1729147854973 | G34: -0.018277632373220002 | H34: DALLE A FAIRE
A35: 34 | B35: 5 | C35: 14305 | D35: Gonneville-sur-Mer | E35: Dalle PDR | F35: 49.30743072574444 | G35: -0.04299704903332074 | H35: DALLE A FAIRE | I35: A AGRANDIR
A36: 35 | B36: 5 | C36: 14305 | D36: Gonneville-sur-Mer | E36: Dalle PDR | F36: 49.2935959 | G36: -0.0119519 | H36: DALLE A FAIRE | I36: A AGRANDIR
A37: 36 | B37: 5 | C37: 14305 | D37: Gonneville-sur-Mer | E37: Dalle PDR | F37: 49.29288803188187 | G37: -0.043396015846523056 | H37: DALLE A FAIRE | I37: A CRÉER
A38: 37 | B38: 5 | C38: 14305 | D38: Gonneville-sur-Mer | E38: Dalle PDR | F38: 49.2828881 | G38: -0.0139663 | H38: DALLE A FAIRE | I38: A AGRANDIR
A39: 38 | B39: 5 | C39: 14305 | D39: Gonneville-sur-Mer | E39: Dalle PDR | F39: 49.2859596 | G39: -0.0412631 | H39: DALLE A FAIRE | I39: A AGRANDIR
A40: 39 | B40: 5 | C40: 14305 | D40: Gonneville-sur-Mer | E40: Dalle PDR | F40: 49.2700973 | G40: -0.0352885 | H40: DALLE A FAIRE | I40: A AGRANDIR
...

Sheet PRESENTATION
A1: PRIORISATION DES COMMUNES — DALLES BÉTON
A2: Source : feuille Feuil2 (score pondéré et classes de priorité) et table BDD_SUIVI_CHANTIERS
A4: 1. CLASSEMENT PAR SCORE DE PRIORITÉ
A5: Rang | B5: Commune | C5: Score pondéré | D5: Classe | E5: Cabanes à cartons | F5: PDR | G5: Bornes à verre | H5: Total dalles à créer
A6: {=_xlfn.SEQUENCE(38)} -> 1 | B6: {=_xlfn.SORTBY('PRIORISATION-1'!$B$24:$B$61,'PRIORISATION-1'!$H$24:$H$61,-1)} -> Cabourg | C6: {=_xlfn.SORTBY('PRIORISATION-1'!$H$24:$H$61,'PRIORISATION-1'!$H$24:$H$61,-1)} -> 72 | D6: {=_xlfn.SORTBY('PRIORISATION-1'!$G$24:$G$61,'PRIORISATION-1'!$H$24:$H$61,-1)} -> P1 - Critique | E6: {=_xlfn.SORTBY('PRIORISATION-1'!$D$24:$D$61,'PRIORISATION-1'!$H$24:$H$61,-1)} -> 2 | F6: {=_xlfn.SORTBY('PRIORISATION-1'!$E$24:$E$61,'PRIORISATION-1'!$H$24:$H$61,-1)} -> 2 | G6: {=_xlfn.SORTBY('PRIORISATION-1'!$F$24:$F$61,'PRIORISATION-1'!$H$24:$H$61,-1)} -> 3 | H6: =E6+F6+G6 -> 7
A7: 2 | B7: Houlgate | C7: 69 | D7: P1 - Critique | E7: 1 | F7: 6 | G7: 1 | H7: =E7+F7+G7 -> 8
A8: 3 | B8: Grangues | C8: 65 | D8: P1 - Critique | E8: 1 | F8: 8 | G8: 0 | H8: =E8+F8+G8 -> 9
A9: 4 | B9: Victot-en-Auge | C9: 64 | D9: P1 - Critique | E9: 2 | F9: 6 | G9: 1 | H9: =E9+F9+G9 -> 9
A10: 5 | B10: Gonneville-sur-Mer | C10: 63 | D10: P1 - Critique | E10: 0 | F10: 10 | G10: 2 | H10: =E10+F10+G10 -> 12
A11: 6 | B11: Dozulé | C11: 59 | D11: P1 - Critique | E11: 3 | F11: 9 | G11: 1 | H11: =E11+F11+G11 -> 13
A12: 7 | B12: Dives-sur-Mer | C12: 57 | D12: P1 - Critique | E12: 0 | F12: 3 | G12: 4 | H12: =E12+F12+G12 -> 7
A13: 8 | B13: Gonneville-en-Auge | C13: 54 | D13: P2 - Haute | E13: 1 | F13: 3 | G13: 1 | H13: =E13+F13+G13 -> 5
A14: 9 | B14: Sallenelles | C14: 49 | D14: P2 - Haute | E14: 1 | F14: 2 | G14: 1 | H14: =E14+F14+G14 -> 4
A15: 10 | B15: Varaville | C15: 49 | D15: P2 - Haute | E15: 0 | F15: 4 | G15: 1 | H15: =E15+F15+G15 -> 5
A16: 11 | B16: Merville-Franceville-Plage | C16: 48 | D16: P2 - Haute | E16: 0 | F16: 2 | G16: 2 | H16: =E16+F16+G16 -> 4
A17: 12 | B17: Angerville | C17: 45 | D17: P2 - Haute | E17: 0 | F17: 4 | G17: 0 | H17: =E17+F17+G17 -> 4
A18: 13 | B18: Cricqueville-en-Auge | C18: 45 | D18: P2 - Haute | E18: 1 | F18: 1 | G18: 0 | H18: =E18+F18+G18 -> 2
... A43: 38 | B43: Touffréville | C43: 0 | D43: P4 - Basse | E43: 0 | F43: 0 | G43: 0 | H43: =E43+F43+G43 -> 0
A46: 2. VAGUES DE TRAVAUX PAR CLASSE DE PRIORITÉ
A47: Vague | B47: Nb communes | C47: Cabanes à cartons | D47: PDR | E47: Bornes à verre | F47: Total dalles
A48: P1 - Critique | B48: =COUNTIF($D$6:$D$43,$A48) -> 7 | C48: =SUMIF($D$6:$D$43,$A48,E$6:E$43) -> 9 | D48: =SUMIF($D$6:$D$43,$A48,F$6:F$43) -> 44 | E48: =SUMIF($D$6:$D$43,$A48,G$6:G$43) -> 12 | F48: =SUMIF($D$6:$D$43,$A48,H$6:H$43) -> 65
A49: P2 - Haute | B49: =COUNTIF($D$6:$D$43,$A49) -> 9 | C49: =SUMIF($D$6:$D$43,$A49,E$6:E$43) -> 6 | D49: =SUMIF($D$6:$D$43,$A49,F$6:F$43) -> 23 | E49: =SUMIF($D$6:$D$43,$A49,G$6:G$43) -> 6 | F49: =SUMIF($D$6:$D$43,$A49,H$6:H$43) -> 35
A50: P3 - Moyenne | B50: =COUNTIF($D$6:$D$43,$A50) -> 6 | C50: =SUMIF($D$6:$D$43,$A50,E$6:E$43) -> 2 | D50: =SUMIF($D$6:$D$43,$A50,F$6:F$43) -> 8 | E50: =SUMIF($D$6:$D$43,$A50,G$6:G$43) -> 4 | F50: =SUMIF($D$6:$D$43,$A50,H$6:H$43) -> 14
A51: P4 - Basse | B51: =COUNTIF($D$6:$D$43,$A51) -> 16 | C51: =SUMIF($D$6:$D$43,$A51,E$6:E$43) -> 3 | D51: =SUMIF($D$6:$D$43,$A51,F$6:F$43) -> 18 | E51: =SUMIF($D$6:$D$43,$A51,G$6:G$43) -> 7 | F51: =SUMIF($D$6:$D$43,$A51,H$6:H$43) -> 28
A52: TOTAL | B52: =SUM(B48:B51) -> 38 | C52: =SUM(C48:C51) -> 20 | D52: =SUM(D48:D51) -> 93 | E52: =SUM(E48:E51) -> 29 | F52: =SUM(F48:F51) -> 142
A54: Communes par vague
A55: P1 - Critique | B55: {=_xlfn.TEXTJOIN(" / ",TRUE,_xlfn._xlws.FILTER($B$6:$B$43,$D$6:$D$43=$A55))} -> Cabourg / Houlgate / Grangues / Victot-en-Auge / Gonneville-sur-Mer / Dozulé / Dives-sur-Mer
A56: P2 - Haute | B56: {=_xlfn.TEXTJOIN(" / ",TRUE,_xlfn._xlws.FILTER($B$6:$B$43,$D$6:$D$43=$A56))} -> Gonneville-en-Auge / Sallenelles / Varaville / Merville-Franceville-Plage / Angerville / Cricqueville-en-Auge / Rumesnil / Beuvron-en-Auge / Saint-Jouin
A57: P3 - Moyenne | B57: {=_xlfn.TEXTJOIN(" / ",TRUE,_xlfn._xlws.FILTER($B$6:$B$43,$D$6:$D$43=$A57))} -> Douville-en-Auge / Beaufour-Druval / Cresseveuille / Amfreville / Hotot-en-Auge / Goustranville
A58: P4 - Basse | B58: {=_xlfn.TEXTJOIN(" / ",TRUE,_xlfn._xlws.FILTER($B$6:$B$43,$D$6:$D$43=$A58))} -> Brucourt / Bavent / Basseneville / Putot-en-Auge / Ranville / Escoville / Auberville / Bréville-les-Monts / Heuland / Saint-Léger-Dubosq / Saint-Vaast-en-Auge / Hérouvillette / Périers-en-Auge / Petiville / Saint-Samson / Touffréville

Sheet CHANTIERS
G1: le niveau de priorité est à retrouver dans le fichier de préparation du dashboard
A2: Code INSEE | B2: Nom commune | C2: Type chantier | D2: latitude | E2: longitude | F2: Aperçu Google Maps | G2: Niveau de priorité (1 : priorité max) | H2: Convention retournée signée | I2: Implantation validée par commune Oui/ Non Courier / mail | J2: DT-DICT Réalisée Oui / non | K2: Retour DT-DICT Vérification emprise sous sol | L2: Validation NCPA / Commune = arrete de circulation /travaux | M2: Communication NCPA + Panneaux signalisation sur site | N2: Début travaux | O2: Fin travaux | P2: Mise en place équipements
A3: 14009 | B3: Amfreville | C3: Dalle cabane à cartons | D3: 49.25562438639887 | E3: -0.22937048501071255 | F3: =+IFERROR(HYPERLINK("https://www.google.com/maps/search/?api=1&query="&D3&","&E3,"Voir sur Maps"),"") -> Voir sur Maps | G3: =+VLOOKUP(TEXT(Tableau1[[#This Row],[Code INSEE]],"00000"),'[1]03_Déploiement_Prévu'!$A$3:$T$40,20,FALSE) -> 4 | H3: =+IF(ISBLANK(VLOOKUP(Tableau1[[#This Row],[Code INSEE]],SYNTHESE_TRAVAUX!$A$2:$J$39,10,FALSE())),"")
A4: 14227 | B4: Douville-en-Auge | C4: Dalle cabane à cartons | D4: 49.26292162057444 | E4: -0.02560165758868783 | F4: =+IFERROR(HYPERLINK("https://www.google.com/maps/search/?api=1&query="&D4&","&E4,"Voir sur Maps"),"") -> Voir sur Maps | G4: =+VLOOKUP(TEXT(Tableau1[[#This Row],[Code INSEE]],"00000"),'[1]03_Déploiement_Prévu'!$A$3:$T$40,20,FALSE) -> 2 | H4: =+IF(ISBLANK(VLOOKUP(Tableau1[[#This Row],[Code INSEE]],SYNTHESE_TRAVAUX!$A$2:$J$39,10,FALSE())),"")
A5: 14227 | B5: Douville-en-Auge | C5: Dalle cabane à cartons | D5: 49.25925414688828 | E5: -0.03461446299042841 | F5: =+IFERROR(HYPERLINK("https://www.google.com/maps/search/?api=1&query="&D5&","&E5,"Voir sur Maps"),"") -> Voir sur Maps | G5: =+VLOOKUP(TEXT(Tableau1[[#This Row],[Code INSEE]],"00000"),'[1]03_Déploiement_Prévu'!$A$3:$T$40,20,FALSE) -> 2 | H5: =+IF(ISBLANK(VLOOKUP(Tableau1[[#This Row],[Code INSEE]],SYNTHESE_TRAVAUX!$A$2:$J$39,10,FALSE())),"")
A6: 14524 | B6: Putot-en-Auge | C6: Dalle cabane à cartons | D6: 49.221084181777954 | E6: -0.07562742766276201 | F6: =+IFERROR(HYPERLINK("https://www.google.com/maps/search/?api=1&query="&D6&","&E6,"Voir sur Maps"),"") -> Voir sur Maps | G6: =+VLOOKUP(TEXT(Tableau1[[#This Row],[Code INSEE]],"00000"),'[1]03_Déploiement_Prévu'!$A$3:$T$40,20,FALSE) -> 3 | H6: =+IF(ISBLANK(VLOOKUP(Tableau1[[#This Row],[Code INSEE]],SYNTHESE_TRAVAUX!$A$2:$J$39,10,FALSE())),"")
A7: 14665 | B7: Sallenelles | C7: Dalle cabane à cartons | D7: 49.264999149825904 | E7: -0.22614302048322546 | F7: =+IFERROR(HYPERLINK("https://www.google.com/maps/search/?api=1&query="&D7&","&E7,"Voir sur Maps"),"") -> Voir sur Maps | G7: =+VLOOKUP(TEXT(Tableau1[[#This Row],[Code INSEE]],"00000"),'[1]03_Déploiement_Prévu'!$A$3:$T$40,20,FALSE) -> 1 | H7: =+IF(ISBLANK(VLOOKUP(Tableau1[[#This Row],[Code INSEE]],SYNTHESE_TRAVAUX!$A$2:$J$39,10,FALSE())),"")
A8: 14743 | B8: Victot-en-Auge | C8: Dalle cabane à cartons | D8: 49.17289832707203 | E8: -0.018312847925501575 | F8: =+IFERROR(HYPERLINK("https://www.google.com/maps/search/?api=1&query="&D8&","&E8,"Voir sur Maps"),"") -> Voir sur Maps | G8: =+VLOOKUP(TEXT(Tableau1[[#This Row],[Code INSEE]],"00000"),'[1]03_Déploiement_Prévu'!$A$3:$T$40,20,FALSE) -> 1 | H8: =+IF(ISBLANK(VLOOKUP(Tableau1[[#This Row],[Code INSEE]],SYNTHESE_TRAVAUX!$A$2:$J$39,10,FALSE())),"")
A9: 14009 | B9: Amfreville | C9: Dalle borne à verre | D9: 49.25566199427314 | E9: -0.22938853639403137 | F9: =+IFERROR(HYPERLINK("https://www.google.com/maps/search/?api=1&query="&D9&","&E9,"Voir sur Maps"),"") -> Voir sur Maps | G9: =+VLOOKUP(TEXT(Tableau1[[#This Row],[Code INSEE]],"00000"),'[1]03_Déploiement_Prévu'!$A$3:$T$40,20,FALSE) -> 4 | H9: =+IF(ISBLANK(VLOOKUP(Tableau1[[#This Row],[Code INSEE]],SYNTHESE_TRAVAUX!$A$2:$J$39,10,FALSE())),"")
A10: 14009 | B10: Amfreville | C10: Dalle borne à verre | D10: 49.24970995591638 | E10: -0.23556659122746876 | F10: =+IFERROR(HYPERLINK("https://www.google.com/maps/search/?api=1&query="&D10&","&E10,"Voir sur Maps"),"") -> Voir sur Maps | G10: =+VLOOKUP(TEXT(Tableau1[[#This Row],[Code INSEE]],"00000"),'[1]03_Déploiement_Prévu'!$A$3:$T$40,20,FALSE) -> 4 | H10: =+IF(ISBLANK(VLOOKUP(Tableau1[[#This Row],[Code INSEE]],SYNTHESE_TRAVAUX!$A$2:$J$39,10,FALSE())),"")
A11: 14024 | B11: Auberville | C11: Dalle borne à verre | D11: 49.30771517 | E11: -0.03637513 | F11: =+IFERROR(HYPERLINK("https://www.google.com/maps/search/?api=1&query="&D11&","&E11,"Voir sur Maps"),"") -> Voir sur Maps | G11: =+VLOOKUP(TEXT(Tableau1[[#This Row],[Code INSEE]],"00000"),'[1]03_Déploiement_Prévu'!$A$3:$T$40,20,FALSE) -> 4 | H11: =+IF(ISBLANK(VLOOKUP(Tableau1[[#This Row],[Code INSEE]],SYNTHESE_TRAVAUX!$A$2:$J$39,10,FALSE())),"")
A12: 14046 | B12: Bavent | C12: Dalle borne à verre | D12: 49.23489736377922 | E12: -0.14660517272742066 | F12: =+IFERROR(HYPERLINK("https://www.google.com/maps/search/?api=1&query="&D12&","&E12,"Voir sur Maps"),"") -> Voir sur Maps | G12: =+VLOOKUP(TEXT(Tableau1[[#This Row],[Code INSEE]],"00000"),'[1]03_Déploiement_Prévu'!$A$3:$T$40,20,FALSE) -> 4 | H12: =+IF(ISBLANK(VLOOKUP(Tableau1[[#This Row],[Code INSEE]],SYNTHESE_TRAVAUX!$A$2:$J$39,10,FALSE())),"")
A13: 14046 | B13: Bavent | C13: Dalle borne à verre | D13: 49.23835257305759 | E13: -0.18889293695664308 | F13: =+IFERROR(HYPERLINK("https://www.google.com/maps/search/?api=1&query="&D13&","&E13,"Voir sur Maps"),"") -> Voir sur Maps | G13: =+VLOOKUP(TEXT(Tableau1[[#This Row],[Code INSEE]],"00000"),'[1]03_Déploiement_Prévu'!$A$3:$T$40,20,FALSE) -> 4 | H13: =+IF(ISBLANK(VLOOKUP(Tableau1[[#This Row],[Code INSEE]],SYNTHESE_TRAVAUX!$A$2:$J$39,10,FALSE())),"")
A14: 14110 | B14: Brucourt | C14: Dalle borne à verre | D14: 49.24471428769877 | E14: -0.10471671057294427 | F14: =+IFERROR(HYPERLINK("https://www.google.com/maps/search/?api=1&query="&D14&","&E14,"Voir sur Maps"),"") -> Voir sur Maps | G14: =+VLOOKUP(TEXT(Tableau1[[#This Row],[Code INSEE]],"00000"),'[1]03_Déploiement_Prévu'!$A$3:$T$40,20,FALSE) -> 3 | H14: =+IF(ISBLANK(VLOOKUP(Tableau1[[#This Row],[Code INSEE]],SYNTHESE_TRAVAUX!$A$2:$J$39,10,FALSE())),"")
... A64: 14227 | B64: Douville-en-Auge | C64: Dalle PDR | D64: 49.2744908 | E64: -0.0135411 | F64: =+IFERROR(HYPERLINK("https://www.google.com/maps/search/?api=1&query="&D64&","&E64,"Voir sur Maps"),"") -> Voir sur Maps | G64: =+VLOOKUP(TEXT(Tableau1[[#This Row],[Code INSEE]],"00000"),'[1]03_Déploiement_Prévu'!$A$3:$T$40,20,FALSE) -> 2 | H64: =+IF(ISBLANK(VLOOKUP(Tableau1[[#This Row],[Code INSEE]],SYNTHESE_TRAVAUX!$A$2:$J$39,10,FALSE())),"")
A65: 14229 | B65: Dozulé | C65: Dalle PDR | D65: 0 | F65: =+IFERROR(HYPERLINK("https://www.google.com/maps/search/?api=1&query="&D65&","&E65,"Voir sur Maps"),"") -> Voir sur Maps | G65: =+VLOOKUP(TEXT(Tableau1[[#This Row],[Code INSEE]],"00000"),'[1]03_Déploiement_Prévu'!$A$3:$T$40,20,FALSE) -> 1 | H65: =+IF(ISBLANK(VLOOKUP(Tableau1[[#This Row],[Code INSEE]],SYNTHESE_TRAVAUX!$A$2:$J$39,10,FALSE())),"")
A66: 14229 | B66: Dozulé | C66: Dalle PDR | D66: 49.23186249899733 | E66: -0.04595250406602712 | F66: =+IFERROR(HYPERLINK("https://www.google.com/maps/search/?api=1&query="&D66&","&E66,"Voir sur Maps"),"") -> Voir sur Maps | G66: =+VLOOKUP(TEXT(Tableau1[[#This Row],[Code INSEE]],"00000"),'[1]03_Déploiement_Prévu'!$A$3:$T$40,20,FALSE) -> 1 | H66: =+IF(ISBLANK(VLOOKUP(Tableau1[[#This Row],[Code INSEE]],SYNTHESE_TRAVAUX!$A$2:$J$39,10,FALSE())),"")
A67: 14229 | B67: Dozulé | C67: Dalle PDR | D67: 49.22958086528844 | E67: -0.0444975878721113 | F67: =+IFERROR(HYPERLINK("https://www.google.com/maps/search/?api=1&query="&D67&","&E67,"Voir sur Maps"),"") -> Voir sur Maps | G67: =+VLOOKUP(TEXT(Tableau1[[#This Row],[Code INSEE]],"00000"),'[1]03_Déploiement_Prévu'!$A$3:$T$40,20,FALSE) -> 1 | H67: =+IF(ISBLANK(VLOOKUP(Tableau1[[#This Row],[Code INSEE]],SYNTHESE_TRAVAUX!$A$2:$J$39,10,FALSE())),"")
A68: 14229 | B68: Dozulé | C68: Dalle PDR | D68: 49.23501849598916 | E68: -0.036048885810860805 | F68: =+IFERROR(HYPERLINK("https://www.google.com/maps/search/?api=1&query="&D68&","&E68,"Voir sur Maps"),"") -> Voir sur Maps | G68: =+VLOOKUP(TEXT(Tableau1[[#This Row],[Code INSEE]],"00000"),'[1]03_Déploiement_Prévu'!$A$3:$T$40,20,FALSE) -> 1 | H68: =+IF(ISBLANK(VLOOKUP(Tableau1[[#This Row],[Code INSEE]],SYNTHESE_TRAVAUX!$A$2:$J$39,10,FALSE())),"")
A69: 14229 | B69: Dozulé | C69: Dalle PDR | D69: 49.2262862 | E69: -0.0363922 | F69: =+IFERROR(HYPERLINK("https://www.google.com/maps/search/?api=1&query="&D69&","&E69,"Voir sur Maps"),"") -> Voir sur Maps | G69: =+VLOOKUP(TEXT(Tableau1[[#This Row],[Code INSEE]],"00000"),'[1]03_Déploiement_Prévu'!$A$3:$T$40,20,FALSE) -> 1 | H69: =+IF(ISBLANK(VLOOKUP(Tableau1[[#This Row],[Code INSEE]],SYNTHESE_TRAVAUX!$A$2:$J$39,10,FALSE())),"")
A70: 14229 | B70: Dozulé | C70: Dalle PDR | D70: 49.2262862 | E70: -0.0363922 | F70: =+IFERROR(HYPERLINK("https://www.google.com/maps/search/?api=1&query="&D70&","&E70,"Voir sur Maps"),"") -> Voir sur Maps | G70: =+VLOOKUP(TEXT(Tableau1[[#This Row],[Code INSEE]],"00000"),'[1]03_Déploiement_Prévu'!$A$3:$T$40,20,FALSE) -> 1 | H70: =+IF(ISBLANK(VLOOKUP(Tableau1[[#This Row],[Code INSEE]],SYNTHESE_TRAVAUX!$A$2:$J$39,10,FALSE())),"")
A71: 14229 | B71: Dozulé | C71: Dalle PDR | D71: 49.2235272 | E71: -0.0429368 | F71: =+IFERROR(HYPERLINK("https://www.google.com/maps/search/?api=1&query="&D71&","&E71,"Voir sur Maps"),"") -> Voir sur Maps | G71: =+VLOOKUP(TEXT(Tableau1[[#This Row],[Code INSEE]],"00000"),'[1]03_Déploiement_Prévu'!$A$3:$T$40,20,FALSE) -> 1 | H71: =+IF(ISBLANK(VLOOKUP(Tableau1[[#This Row],[Code INSEE]],SYNTHESE_TRAVAUX!$A$2:$J$39,10,FALSE())),"")
A72: 14229 | B72: Dozulé | C72: Dalle PDR | D72: 49.2336129 | E72: -0.049873 | F72: =+IFERROR(HYPERLINK("https://www.google.com/maps/search/?api=1&query="&D72&","&E72,"Voir sur Maps"),"") -> Voir sur Maps | G72: =+VLOOKUP(TEXT(Tableau1[[#This Row],[Code INSEE]],"00000"),'[1]03_Déploiement_Prévu'!$A$3:$T$40,20,FALSE) -> 1 | H72: =+IF(ISBLANK(VLOOKUP(Tableau1[[#This Row],[Code INSEE]],SYNTHESE_TRAVAUX!$A$2:$J$39,10,FALSE())),"")
A73: 14229 | B73: Dozulé | C73: Dalle PDR | D73: 49.2336129 | E73: -0.049873 | F73: =+IFERROR(HYPERLINK("https://www.google.com/maps/search/?api=1&query="&D73&","&E73,"Voir sur Maps"),"") -> Voir sur Maps | G73: =+VLOOKUP(TEXT(Tableau1[[#This Row],[Code INSEE]],"00000"),'[1]03_Déploiement_Prévu'!$A$3:$T$40,20,FALSE) -> 1 | H73: =+IF(ISBLANK(VLOOKUP(Tableau1[[#This Row],[Code INSEE]],SYNTHESE_TRAVAUX!$A$2:$J$39,10,FALSE())),"")
A74: 14229 | B74: Dozulé | C74: Dalle PDR | D74: 49.22913127846012 | E74: -0.04684122951583171 | F74: =+IFERROR(HYPERLINK("https://www.google.com/maps/search/?api=1&query="&D74&","&E74,"Voir sur Maps"),"") -> Voir sur Maps | G74: =+VLOOKUP(TEXT(Tableau1[[#This Row],[Code INSEE]],"00000"),'[1]03_Déploiement_Prévu'!$A$3:$T$40,20,FALSE) -> 1 | H74: =+IF(ISBLANK(VLOOKUP(Tableau1[[#This Row],[Code INSEE]],SYNTHESE_TRAVAUX!$A$2:$J$39,10,FALSE())),"")
A75: 14229 | B75: Dozulé | C75: Dalle PDR | D75: 49.2281552 | E75: -0.0409721 | F75: =+IFERROR(HYPERLINK("https://www.google.com/maps/search/?api=1&query="&D75&","&E75,"Voir sur Maps"),"") -> Voir sur Maps | G75: =+VLOOKUP(TEXT(Tableau1[[#This Row],[Code INSEE]],"00000"),'[1]03_Déploiement_Prévu'!$A$3:$T$40,20,FALSE) -> 1 | H75: =+IF(ISBLANK(VLOOKUP(Tableau1[[#This Row],[Code INSEE]],SYNTHESE_TRAVAUX!$A$2:$J$39,10,FALSE())),"")
A76: 14229 | B76: Dozulé | C76: Dalle PDR | D76: 49.2308675 | E76: -0.0452489 | F76: =+IFERROR(HYPERLINK("https://www.google.com/maps/search/?api=1&query="&D76&","&E76,"Voir sur Maps"),"") -> Voir sur Maps | G76: =+VLOOKUP(TEXT(Tableau1[[#This Row],[Code INSEE]],"00000"),'[1]03_Déploiement_Prévu'!$A$3:$T$40,20,FALSE) -> 1 | H76: =+IF(ISBLANK(VLOOKUP(Tableau1[[#This Row],[Code INSEE]],SYNTHESE_TRAVAUX!$A$2:$J$39,10,FALSE())),"")
A77: 14229 | B77: Dozulé | C77: Dalle PDR | D77: 49.22720999872636 | E77: -0.04248176650664557 | F77: =+IFERROR(HYPERLINK("https://www.google.com/maps/search/?api=1&query="&D77&","&E77,"Voir sur Maps"),"") -> Voir sur Maps | G77: =+VLOOKUP(TEXT(Tableau1[[#This Row],[Code INSEE]],"00000"),'[1]03_Déploiement_Prévu'!$A$3:$T$40,20,FALSE) -> 1 | H77: =+IF(ISBLANK(VLOOKUP(Tableau1[[#This Row],[Code INSEE]],SYNTHESE_TRAVAUX!$A$2:$J$39,10,FALSE())),"")
... A93: 14316 | B93: Grangues | C93: Dalle PDR | D93: 49.2659712 | E93: -0.0646614 | F93: =+IFERROR(HYPERLINK("https://www.google.com/maps/search/?api=1&query="&D93&","&E93,"Voir sur Maps"),"") -> Voir sur Maps | G93: =+VLOOKUP(TEXT(Tableau1[[#This Row],[Code INSEE]],"00000"),'[1]03_Déploiement_Prévu'!$A$3:$T$40,20,FALSE) -> 2 | H93: =+IF(ISBLANK(VLOOKUP(Tableau1[[#This Row],[Code INSEE]],SYNTHESE_TRAVAUX!$A$2:$J$39,10,FALSE())),"")
A94: 14316 | B94: Grangues | C94: Dalle PDR | F94: =+IFERROR(HYPERLINK("https://www.google.com/maps/search/?api=1&query="&D94&","&E94,"Voir sur Maps"),"") -> Voir sur Maps | G94: =+VLOOKUP(TEXT(Tableau1[[#This Row],[Code INSEE]],"00000"),'[1]03_Déploiement_Prévu'!$A$3:$T$40,20,FALSE) -> 2 | H94: =+IF(ISBLANK(VLOOKUP(Tableau1[[#This Row],[Code INSEE]],SYNTHESE_TRAVAUX!$A$2:$J$39,10,FALSE())),"")
A95: 14316 | B95: Grangues | C95: Dalle PDR | F95: =+IFERROR(HYPERLINK("https://www.google.com/maps/search/?api=1&query="&D95&","&E95,"Voir sur Maps"),"") -> Voir sur Maps | G95: =+VLOOKUP(TEXT(Tableau1[[#This Row],[Code INSEE]],"00000"),'[1]03_Déploiement_Prévu'!$A$3:$T$40,20,FALSE) -> 2 | H95: =+IF(ISBLANK(VLOOKUP(Tableau1[[#This Row],[Code INSEE]],SYNTHESE_TRAVAUX!$A$2:$J$39,10,FALSE())),"")
A96: 14329 | B96: Heuland | C96: Dalle PDR | D96: 49.2577836 | E96: -0.0030953 | F96: =+IFERROR(HYPERLINK("https://www.google.com/maps/search/?api=1&query="&D96&","&E96,"Voir sur Maps"),"") -> Voir sur Maps | G96: =+VLOOKUP(TEXT(Tableau1[[#This Row],[Code INSEE]],"00000"),'[1]03_Déploiement_Prévu'!$A$3:$T$40,20,FALSE) -> 4 | H96: =+IF(ISBLANK(VLOOKUP(Tableau1[[#This Row],[Code INSEE]],SYNTHESE_TRAVAUX!$A$2:$J$39,10,FALSE())),"")
A97: 14338 | B97: Houlgate | C97: Dalle PDR | D97: 49.2994049 | E97: -0.0838257 | F97: =+IFERROR(HYPERLINK("https://www.google.com/maps/search/?api=1&query="&D97&","&E97,"Voir sur Maps"),"") -> Voir sur Maps | G97: =+VLOOKUP(TEXT(Tableau1[[#This Row],[Code INSEE]],"00000"),'[1]03_Déploiement_Prévu'!$A$3:$T$40,20,FALSE) -> 4 | H97: =+IF(ISBLANK(VLOOKUP(Tableau1[[#This Row],[Code INSEE]],SYNTHESE_TRAVAUX!$A$2:$J$39,10,FALSE())),"")
